Workbook
Name FechaCorte: PSR!$C$6

Sheet Portada
A11: UNIVERSIDAD AUTÓNOMA DE ZACATECAS
A12: CAMPUS UAZ SIGLO XXI
A13: INGENIERÍA DE SOFTWARE
A15: Sebastián Guerra Hernández
A16: Pablo Valentín Varela Rivera
A17: Francisco Valdez García
A18: Marco Antonio de Jesús Oliva Santos
A19: PSPS
A20: Progress Status Record
A21: Team Software Process
A22: 8 de octubre de 2026

Sheet PSR
A1: Progress Status Record (WP.06) — PSPS
A3: Proyecto | B3: PSPS – Aplicación móvil para la enseñanza de Ingeniería de Software
A4: Cliente | B4: M. L. SIGG
A5: Gestor del proyecto (PJM) | B5: Francisco Valdez García
A6: Fecha de corte | B6: Se actualiza cada vez que se ingresa | C6: 46303
A7: Periodo en curso | B7: =IF(C6<=DATE(2026,9,18),"Sprint 0",IF(C6<=DATE(2026,10,8),"Sprint 1",IF(C6<DATE(2026,10,12),"Entre Sprint 1 y Sprint 2",IF(C6<=DATE(2026,10,26),"Sprint 2",IF(C6<=DATE(2026,11,12),"Sprint 3",IF(C6<DATE(2026,11,16),"Entre Sprint 3 y entrega","Revisión y entrega")))))) -> Sprint 1
A9: 1. Estado de las tareas y horas reales (Sprint 1 conciliado el 10/10; ver Control_Diario)
A10: Tarea (Project Plan) | B10: Descripción | C10: Tareas ISO | D10: Horas plan (total) | E10: Plan a la fecha | F10: Horas reales capturadas | G10: Capturadas − plan al corte | H10: Estado | I10: Resultado / evidencia a la fecha de corte
A11: T01 | B11: Generar, revisar y someter a aprobación el Project Plan; mantenerlo actualizado. | C11: PM.01.01–PM.01.09 | D11: =SUMIF(Control_Diario!$F$2:$F$300,A11,Control_Diario!$J$2:$J$300) -> 12 | E11: =SUMIFS(Control_Diario!$J$2:$J$300,Control_Diario!$F$2:$F$300,A11,Control_Diario!$C$2:$C$300,"<="&FechaCorte) -> 12 | F11: =SUMIFS(Control_Diario!$K$2:$K$300,Control_Diario!$F$2:$F$300,A11,Control_Diario!$C$2:$C$300,"<="&FechaCorte) -> 12 | G11: =IF(AND(F11=0,E11=0),"",F11-E11) -> 0 | H11: En proceso | I11: Project Plan 24/09 aprobado según el equipo; anexar el escaneo firmado con su fecha real. La actualización del calendario se tramita en CR-01, pendiente de aprobación de la cliente.
A12: T02 | B12: Revisar el plan con el equipo; preparar y verificar el entorno por plataforma. | C12: SI.01.01, SI.01.02, PM.01.10 | D12: =SUMIF(Control_Diario!$F$2:$F$300,A12,Control_Diario!$J$2:$J$300) -> 12 | E12: =SUMIFS(Control_Diario!$J$2:$J$300,Control_Diario!$F$2:$F$300,A12,Control_Diario!$C$2:$C$300,"<="&FechaCorte) -> 10 | F12: =SUMIFS(Control_Diario!$K$2:$K$300,Control_Diario!$F$2:$F$300,A12,Control_Diario!$C$2:$C$300,"<="&FechaCorte) -> 10 | G12: =IF(AND(F12=0,E12=0),"",F12-E12) -> 0 | H12: En proceso | I12: MR-02: revisión del plan con el equipo el 22/09; entorno Android reportado. iOS pendiente por falta de Mac/Xcode.
A13: T03 | B13: Analizar y documentar requisitos; crear y refinar el Product Backlog. | C13: SI.02.02 | D13: =SUMIF(Control_Diario!$F$2:$F$300,A13,Control_Diario!$J$2:$J$300) -> 24 | E13: =SUMIFS(Control_Diario!$J$2:$J$300,Control_Diario!$F$2:$F$300,A13,Control_Diario!$C$2:$C$300,"<="&FechaCorte) -> 18 | F13: =SUMIFS(Control_Diario!$K$2:$K$300,Control_Diario!$F$2:$F$300,A13,Control_Diario!$C$2:$C$300,"<="&FechaCorte) -> 43.75 | G13: =IF(AND(F13=0,E13=0),"",F13-E13) -> 25.75 | H13: En proceso | I13: SRS v0.1 revisado el 07/10 y actualizado el 08/10; horas de la actualización incluidas en los ID 103, 105 y 109. Esfuerzo +25.75 h sobre el plan por apoyo no planeado (ver sección 7). RF-07/RF-09 y G-01–G-03 se definen y validan en Sprint 2.
A14: T04 | B14: Validar y obtener aprobación de requisitos con la cliente; ordenar el Product Backlog. | C14: SI.02.03, SI.02.04 | D14: =SUMIF(Control_Diario!$F$2:$F$300,A14,Control_Diario!$J$2:$J$300) -> 14 | E14: =SUMIFS(Control_Diario!$J$2:$J$300,Control_Diario!$F$2:$F$300,A14,Control_Diario!$C$2:$C$300,"<="&FechaCorte) -> 8.5 | F14: =SUMIFS(Control_Diario!$K$2:$K$300,Control_Diario!$F$2:$F$300,A14,Control_Diario!$C$2:$C$300,"<="&FechaCorte) -> 3.75 | G14: =IF(AND(F14=0,E14=0),"",F14-E14) -> -4.75 | H14: En proceso | I14: MR-06 y MR-07 mantienen la aprobación del SRS pendiente. Preparación registrada; no acredita aprobación.
A15: T05 | B15: Identificar y documentar componentes e interfaces de los elementos seleccionados. | C15: SI.03.03 | D15: =SUMIF(Control_Diario!$F$2:$F$300,A15,Control_Diario!$J$2:$J$300) -> 24 | E15: =SUMIFS(Control_Diario!$J$2:$J$300,Control_Diario!$F$2:$F$300,A15,Control_Diario!$C$2:$C$300,"<="&FechaCorte) -> 13 | F15: =SUMIFS(Control_Diario!$K$2:$K$300,Control_Diario!$F$2:$F$300,A15,Control_Diario!$C$2:$C$300,"<="&FechaCorte) -> 10.25 | G15: =IF(AND(F15=0,E15=0),"",F15-E15) -> -2.75 | H15: En proceso | I15: El análisis de componentes e interfaces inició el 23/09 (ID 22), como planeó la Daily D-03, después de la revisión del Project Plan en MR-02 (22/09). Daily D-05 (25/09) lo registra en elaboración. Primer borrador del SDS: 06/10. SDS v0.1 revisado internamente el 08/10 y alineado al SRS v0.1; faltan la revisión formal del diseño y su aprobación.
A16: T06 | B16: Revisar el diseño antes de construir los componentes correspondientes. | C16: SI.03.02, SI.03.04 | D16: =SUMIF(Control_Diario!$F$2:$F$300,A16,Control_Diario!$J$2:$J$300) -> 12 | E16: =SUMIFS(Control_Diario!$J$2:$J$300,Control_Diario!$F$2:$F$300,A16,Control_Diario!$C$2:$C$300,"<="&FechaCorte) -> 6.5 | F16: =SUMIFS(Control_Diario!$K$2:$K$300,Control_Diario!$F$2:$F$300,A16,Control_Diario!$C$2:$C$300,"<="&FechaCorte) -> 5.25 | G16: =IF(AND(F16=0,E16=0),"",F16-E16) -> -1.25 | H16: En proceso | I16: MR-06 documenta revisión del SRS el 07/10. Revisiones posteriores y aprobación del diseño por completar; horas individuales registradas al corte.
A17: T07 | B17: Construir los componentes del alcance seleccionado. | C17: SI.04.02, SI.04.05 | D17: =SUMIF(Control_Diario!$F$2:$F$300,A17,Control_Diario!$J$2:$J$300) -> 90 | E17: =SUMIFS(Control_Diario!$J$2:$J$300,Control_Diario!$F$2:$F$300,A17,Control_Diario!$C$2:$C$300,"<="&FechaCorte) -> 24 | F17: =SUMIFS(Control_Diario!$K$2:$K$300,Control_Diario!$F$2:$F$300,A17,Control_Diario!$C$2:$C$300,"<="&FechaCorte) -> 12.25 | G17: =IF(AND(F17=0,E17=0),"",F17-E17) -> -11.75 | H17: En proceso | I17: Bitácora y MR-03/MR-07 reportan construcción Android. 12.25 h reales frente a 24 h planeadas al corte, desplazadas por el apoyo no planeado al SRS (ver sección 7). Relacionar commits por responsable.
A18: T08 | B18: Preparar y ejecutar pruebas unitarias y de widgets; corregir defectos. | C18: SI.04.03, SI.04.04 | D18: =SUMIF(Control_Diario!$F$2:$F$300,A18,Control_Diario!$J$2:$J$300) -> 36 | E18: =SUMIFS(Control_Diario!$J$2:$J$300,Control_Diario!$F$2:$F$300,A18,Control_Diario!$C$2:$C$300,"<="&FechaCorte) -> 8 | F18: =SUMIFS(Control_Diario!$K$2:$K$300,Control_Diario!$F$2:$F$300,A18,Control_Diario!$C$2:$C$300,"<="&FechaCorte) -> 3.75 | G18: =IF(AND(F18=0,E18=0),"",F18-E18) -> -4.25 | H18: En proceso | I18: MR-07 reporta 10 pruebas automáticas aprobadas. Horas registradas por integrante; faltan casos/logs (WP.14) y no consta cierre de todos los componentes.
A19: T09 | B19: Integrar componentes durante el Sprint conforme se completen. | C19: SI.05.03 | D19: =SUMIF(Control_Diario!$F$2:$F$300,A19,Control_Diario!$J$2:$J$300) -> 18 | E19: =SUMIFS(Control_Diario!$J$2:$J$300,Control_Diario!$F$2:$F$300,A19,Control_Diario!$C$2:$C$300,"<="&FechaCorte) -> 4 | F19: =SUMIFS(Control_Diario!$K$2:$K$300,Control_Diario!$F$2:$F$300,A19,Control_Diario!$C$2:$C$300,"<="&FechaCorte) -> 1.25 | G19: =IF(AND(F19=0,E19=0),"",F19-E19) -> -2.75 | H19: En proceso | I19: MR-03/MR-07 reportan incremento integrado Android. Horas registradas; relacionar versión/commit.
A20: T10 | B20: Ejecutar pruebas de integración, registrar resultados y corregir defectos. | C20: SI.05.02, SI.05.04, SI.05.05 | D20: =SUMIF(Control_Diario!$F$2:$F$300,A20,Control_Diario!$J$2:$J$300) -> 30 | E20: =SUMIFS(Control_Diario!$J$2:$J$300,Control_Diario!$F$2:$F$300,A20,Control_Diario!$C$2:$C$300,"<="&FechaCorte) -> 6 | F20: =SUMIFS(Control_Diario!$K$2:$K$300,Control_Diario!$F$2:$F$300,A20,Control_Diario!$C$2:$C$300,"<="&FechaCorte) -> 2.25 | G20: =IF(AND(F20=0,E20=0),"",F20-E20) -> -3.75 | H20: En proceso | I20: MR-07 reporta 1 prueba de integración Android. Modo avión e iOS pendientes; faltan registros técnicos (WP.15). Esfuerzo registrado.
A21: T11 | B21: Realizar Sprint Review y registrar acuerdos; validar el producto final. | C21: PM.02.02, SI.05.06 | D21: =SUMIF(Control_Diario!$F$2:$F$300,A21,Control_Diario!$J$2:$J$300) -> 16 | E21: =SUMIFS(Control_Diario!$J$2:$J$300,Control_Diario!$F$2:$F$300,A21,Control_Diario!$C$2:$C$300,"<="&FechaCorte) -> 4 | F21: =SUMIFS(Control_Diario!$K$2:$K$300,Control_Diario!$F$2:$F$300,A21,Control_Diario!$C$2:$C$300,"<="&FechaCorte) -> 7 | G21: =IF(AND(F21=0,E21=0),"",F21-E21) -> 3 | H21: En proceso | I21: MR-03 (02/10) y MR-07 (08/10): revisiones internas del incremento, sin la cliente. Pendiente: Sprint Review con la cliente en el Sprint 2 y validación final.
A22: T12 | B22: Preparar la versión entregable, la guía de operación y el paquete de entrega. | C22: SI.06.01, SI.06.02 | D22: =SUMIF(Control_Diario!$F$2:$F$300,A22,Control_Diario!$J$2:$J$300) -> 32 | E22: =SUMIFS(Control_Diario!$J$2:$J$300,Control_Diario!$F$2:$F$300,A22,Control_Diario!$C$2:$C$300,"<="&FechaCorte) -> 4 | F22: =SUMIFS(Control_Diario!$K$2:$K$300,Control_Diario!$F$2:$F$300,A22,Control_Diario!$C$2:$C$300,"<="&FechaCorte) -> 4 | G22: =IF(AND(F22=0,E22=0),"",F22-E22) -> 0 | H22: Pendiente | I22: Se registraron 4 h de preparación en Sprint 1. Las instrucciones de entrega están en el Project Plan; la Guía de operación final sigue pendiente.
... A24: T14 | B24: Monitorear esfuerzo, avance, reuniones, cambios, riesgos y desviaciones. | C24: PM.02.01, PM.03.01–PM.03.03 | D24: =SUMIF(Control_Diario!$F$2:$F$300,A24,Control_Diario!$J$2:$J$300) -> 68 | E24: =SUMIFS(Control_Diario!$J$2:$J$300,Control_Diario!$F$2:$F$300,A24,Control_Diario!$C$2:$C$300,"<="&FechaCorte) -> 26 | F24: =SUMIFS(Control_Diario!$K$2:$K$300,Control_Diario!$F$2:$F$300,A24,Control_Diario!$C$2:$C$300,"<="&FechaCorte) -> 27.5 | G24: =IF(AND(F24=0,E24=0),"",F24-E24) -> 1.5 | H24: En proceso | I24: MR-01: Planning 21/09; MR-04: mejora intermedia 02/10; MR-05: ajuste 05/10; MR-07: cierre 08/10. Dailies D-01 a D-14 al corte; D-15 en la bitácora de seguimiento posterior. Pendiente: Planning del Sprint 2 (12/10).
A25: Total | D25: =SUM(D11:D24) -> 396 | E25: =SUM(E11:E24) -> 144 | F25: =SUM(F11:F24) -> 143 | G25: =F25-E25 -> -1
A27: 2. Indicadores de avance y esfuerzo al corte
A28: Indicador | B28: Cómo se calcula | D28: Valor | I28: Cómo leerlo
A29: Valor planeado (PV) | B29: Horas plan a la fecha ÷ horas plan totales | D29: =IF(D25=0,0,E25/D25) -> 0.36363636 | I29: Lo que ya debería estar hecho según el plan.
A30: Valor ganado (EV) | B30: Horas estimadas de filas «Completado» ÷ horas plan totales | D30: =IF(D25=0,0,SUMIFS(Control_Diario!$J$2:$J$300,Control_Diario!$L$2:$L$300,"Completado",Control_Diario!$C$2:$C$300,"<="&FechaCorte)/D25) -> 0.33838384 | I30: Lo que realmente se terminó.
A31: SPI (EV ÷ PV) | B31: Índice de desempeño del cronograma | D31: =IF(D29=0,0,D30/D29) -> 0.93055556 | I31: Menor que 1: vamos atrasados. Mayor que 1: adelantados.
A32: CPI de filas completadas | B32: Horas estimadas ÷ horas reales de las filas «Completado» | D32: =IF(SUMIFS(Control_Diario!$K$2:$K$300,Control_Diario!$L$2:$L$300,"Completado",Control_Diario!$C$2:$C$300,"<="&FechaCorte)=0,0,SUMIFS(Control_Diario!$J$2:$J$300,Control_Diario!$L$2:$L$300,"Completado",Control_Diario!$C$2:$C$300,"<="&FechaCorte)/SUMIFS(Control_Diario!$K$2:$K$300,Control_Diario!$L$2:$L$300,"Completado",Control_Diario!$C$2:$C$300,"<="&FechaCorte)) -> 0.97632058 | I32: Solo filas completadas; excluye esfuerzo en proceso. No representa la eficiencia global.
A33: Horas reales capturadas | B33: Suma de horas reales del Control_Diario | D33: =F25 -> 143 | I33: 143 h reales registradas al corte, conciliadas con la bitácora y las minutas. El ID 268 (revisión del SDS v0.1 del 08/10) no suma horas propias: su esfuerzo está registrado en los ID 107 y 110.
A35: 3. Resultados vs. objetivos del proyecto (Project Plan §5)
A36: Objetivo específico | C36: Requisitos relacionados | H36: Estado | I36: Resultado a la fecha
A37: Organizar los conceptos en módulos o temas claros y estructurados. | C37: RN-02, RF-01, CT-01–CT-10 | H37: En proceso | I37: MR-07 reporta 4 módulos y 10 temas; agrupación definitiva pendiente D-01.
A38: Implementar actividades interactivas sobre situaciones de Ingeniería de Software. | C38: RF-03, CU-02 | H38: En proceso | I38: MR-07 reporta actividad de ordenar pasos. Falta validar contenido y completar gamificación.
A39: Incorporar elementos de gamificación. | C39: RF-06, RF-07, G-01–G-03 | H39: Pendiente | I39: Puntos de demostración reportados; logros/desbloqueos y catálogo pendientes para Sprint 2.
A40: Permitir recorrer los contenidos y visualizar el avance. | C40: RF-02, RF-04, RF-05, RF-08 | H40: En proceso | I40: MR-07 reporta progreso y guardado local; faltan evidencias técnicas y prueba manual modo avión.
A41: Desarrollar una interfaz móvil clara y fácil de usar. | C41: RNF-05 | H41: En proceso | I41: MR-03/MR-07 refieren wireframes y pantallas; validar interfaz y registrar evidencias.
A42: Entregar una versión funcional que cumpla el alcance acordado. | C42: Agreement §4 y §6 | H42: Pendiente | I42: Entrega propuesta del 16 al 20/11/2026 (CR-01).
A44: 4. Recursos: horas disponibles, planeadas y reales por integrante (eventos de equipo ÷ 4)
A45: Integrante | B45: Rol (Project Plan §11) | C45: Disponibilidad teórica | D45: Horas plan (total) | E45: Plan a la fecha | F45: Horas reales atribuidas | G45: Varianza (reales − plan a la fecha) | H45: Uso de horas disponibles | I45: Observaciones
A46: Francisco Valdez García | B46: PJM / Scrum Master / Developer | C46: =IF(FechaCorte<DATE(2026,9,21),0,3*NETWORKDAYS(DATE(2026,9,21),MIN(FechaCorte,DATE(2026,11,12)))) -> 42 | D46: =SUMIF(Control_Diario!$D$2:$D$300,A46,Control_Diario!$J$2:$J$300)+SUMIF(Control_Diario!$D$2:$D$300,"Equipo",Control_Diario!$J$2:$J$300)/4 -> 99 | E46: =SUMIFS(Control_Diario!$J$2:$J$300,Control_Diario!$D$2:$D$300,A46,Control_Diario!$C$2:$C$300,"<="&FechaCorte)+SUMIFS(Control_Diario!$J$2:$J$300,Control_Diario!$D$2:$D$300,"Equipo",Control_Diario!$C$2:$C$300,"<="&FechaCorte)/4 -> 36 | F46: =SUMIFS(Control_Diario!$K$2:$K$300,Control_Diario!$D$2:$D$300,A46,Control_Diario!$C$2:$C$300,"<="&FechaCorte)+SUMIFS(Control_Diario!$K$2:$K$300,Control_Diario!$D$2:$D$300,"Equipo",Control_Diario!$C$2:$C$300,"<="&FechaCorte)/4 -> 35.125 | G46: =F46-E46 -> -0.875 | H46: =IF(C46=0,0,F46/C46) -> 0.83630952 | I46: Horas individuales capturadas más reuniones de equipo ÷ 4. El equipo confirmó que los cuatro asistieron a todas las reuniones.
...

Sheet Control_Diario
A1: ID | B1: Sprint / Periodo | C1: Fecha | D1: Integrante | E1: Rol | F1: Tarea PP | G1: Código ISO | H1: Descripción de la tarea | I1: Work Product | J1: Horas estimadas | K1: Horas reales | L1: Estado | M1: Revisar horas al corte
A2: 6 | B2: Sprint 1 | C2: 46286 | D2: Marco Antonio de Jesús Oliva Santos | E2: WT / Developer – Colaboración | F2: T01 | G2: PM.01.08 | H2: Actualizar el Project Plan y su control de versiones | I2: Project Plan (WP.07) | J2: 1.75 | K2: 1.75 | L2: Completado | M2: =IF(AND(C2<=FechaCorte,NOT(ISNUMBER(K2))),"Por confirmar","")
A3: 3 | B3: Sprint 1 | C3: 46286 | D3: Francisco Valdez García | E3: PJM / Scrum Master / Developer | F3: T01 | G3: PM.01.08–.09 | H3: Generar, revisar y someter a aprobación el Project Plan | I3: Project Plan (WP.07) | J3: 1.75 | K3: 1.75 | L3: Completado | M3: =IF(AND(C3<=FechaCorte,NOT(ISNUMBER(K3))),"Por confirmar","")
A4: 4 | B4: Sprint 1 | C4: 46286 | D4: Sebastián Guerra Hernández | E4: WT / Developer – Calidad | F4: T01 | G4: PM.01.09 | H4: Revisar el Project Plan antes de someterlo a aprobación | I4: Project Plan revisado | J4: 1.75 | K4: 1.75 | L4: Completado | M4: =IF(AND(C4<=FechaCorte,NOT(ISNUMBER(K4))),"Por confirmar","")
A5: 13 | B5: Sprint 1 | C5: 46287 | D5: Marco Antonio de Jesús Oliva Santos | E5: WT / Developer – Colaboración | F5: T01 | G5: PM.01.08 | H5: Actualizar el Project Plan y su control de versiones | I5: Project Plan (WP.07) | J5: 2.25 | K5: 2.25 | L5: Completado | M5: =IF(AND(C5<=FechaCorte,NOT(ISNUMBER(K5))),"Por confirmar","")
A6: 8 | B6: Sprint 1 | C6: 46287 | D6: Francisco Valdez García | E6: PJM / Scrum Master / Developer | F6: T01 | G6: PM.01.08–.09 | H6: Generar, revisar y someter a aprobación el Project Plan | I6: Project Plan (WP.07) | J6: 2.75 | K6: 2.75 | L6: Completado | M6: =IF(AND(C6<=FechaCorte,NOT(ISNUMBER(K6))),"Por confirmar","")
A7: 9 | B7: Sprint 1 | C7: 46287 | D7: Sebastián Guerra Hernández | E7: WT / Developer – Calidad | F7: T01 | G7: PM.01.09 | H7: Revisar el Project Plan antes de someterlo a aprobación | I7: Project Plan revisado | J7: 0.25 | K7: 0.25 | L7: Completado | M7: =IF(AND(C7<=FechaCorte,NOT(ISNUMBER(K7))),"Por confirmar","")
A8: 16 | B8: Sprint 1 | C8: 46288 | D8: Francisco Valdez García | E8: PJM / Scrum Master / Developer | F8: T01 | G8: PM.01.08–.09 | H8: Generar, revisar y someter a aprobación el Project Plan | I8: Project Plan (WP.07) | J8: 1.5 | K8: 1.5 | L8: Completado | M8: =IF(AND(C8<=FechaCorte,NOT(ISNUMBER(K8))),"Por confirmar","")
A9: 5 | B9: Sprint 1 | C9: 46286 | D9: Pablo Valentín Varela Rivera | E9: WT / Developer – Técnico | F9: T02 | G9: SI.01.02 | H9: Preparar y verificar el entorno por plataforma (Flutter, Android, iOS) | I9: Implementation Environment (WP.04) | J9: 1.75 | K9: 1.75 | L9: Completado | M9: =IF(AND(C9<=FechaCorte,NOT(ISNUMBER(K9))),"Por confirmar","")
A10: 14 | B10: Sprint 1 | C10: 46287 | D10: Marco Antonio de Jesús Oliva Santos | E10: WT / Developer – Colaboración | F10: T02 | G10: PM.01.10 | H10: Establecer el repositorio GitHub y GitHub Issues (etiquetas, hitos) | I10: Repositorio (WP.08) | J10: 0.5 | K10: 0.5 | L10: Completado | M10: =IF(AND(C10<=FechaCorte,NOT(ISNUMBER(K10))),"Por confirmar","")
A11: 11 | B11: Sprint 1 | C11: 46287 | D11: Pablo Valentín Varela Rivera | E11: WT / Developer – Técnico | F11: T02 | G11: SI.01.02 | H11: Preparar y verificar el entorno por plataforma (Flutter, Android, iOS) | I11: Implementation Environment (WP.04) | J11: 1.75 | K11: 1.75 | L11: Pendiente | M11: =IF(AND(C11<=FechaCorte,NOT(ISNUMBER(K11))),"Por confirmar","")
A12: 24 | B12: Sprint 1 | C12: 46288 | D12: Marco Antonio de Jesús Oliva Santos | E12: WT / Developer – Colaboración | F12: T02 | G12: PM.01.10 | H12: Establecer el repositorio GitHub y GitHub Issues (etiquetas, hitos) | I12: Repositorio (WP.08) | J12: 2.75 | K12: 2.75 | L12: Completado | M12: =IF(AND(C12<=FechaCorte,NOT(ISNUMBER(K12))),"Por confirmar","")
A13: 31 | B13: Sprint 1 | C13: 46289 | D13: Marco Antonio de Jesús Oliva Santos | E13: WT / Developer – Colaboración | F13: T02 | G13: PM.01.10 | H13: Establecer el repositorio GitHub y GitHub Issues (etiquetas, hitos) | I13: Repositorio (WP.08) | J13: 0.25 | K13: 0.25 | L13: Completado | M13: =IF(AND(C13<=FechaCorte,NOT(ISNUMBER(K13))),"Por confirmar","")
... A115: 269 | B115: Sprint 1 | C115: 46303 | D115: Equipo | E115: Equipo; esfuerzo individual por confirmar | F115: T03 | G115: SI.02.02 | H115: Actualizar SRS a revisión v0.1 | I115: SRS v0.1 (WP.09) | J115: 0 | K115: 0 | L115: Completado | M115: =IF(AND(C115<=FechaCorte,NOT(ISNUMBER(K115))),"Por confirmar","")
A116: 112 | B116: Sprint 2 | C116: 46309 | D116: Francisco Valdez García | E116: PJM / Scrum Master / Developer | F116: T04 | G116: SI.02.03 | H116: Sesión con la cliente al inicio del Sprint: decidir D-01 y D-02 y presentar el SRS v0.1 y el CR-01 (fecha propuesta; agendar con la cliente) | I116: SRS validado (WP.09), Minuta (WP.05) | J116: 2.5 | L116: Pendiente | M116: =IF(AND(C116<=FechaCorte,NOT(ISNUMBER(K116))),"Por confirmar","")
A117: 268 | B117: Sprint 1 | C117: 46303 | D117: Equipo | E117: Equipo; esfuerzo individual por confirmar | F117: T05 | G117: SI.03.03 | H117: Documentar revisión SDS v0.1 basada en SRS v0.1 | I117: SDS v0.1 (WP.12) | J117: 0 | K117: 0 | L117: Completado | M117: =IF(AND(C117<=FechaCorte,NOT(ISNUMBER(K117))),"Por confirmar","")
A118: 118 | B118: Sprint 2 | C118: 46307 | D118: Marco Antonio de Jesús Oliva Santos | E118: WT / Developer – Colaboración | F118: T05 | G118: SI.03.03 | H118: Identificar y documentar componentes e interfaces (SDS) | I118: SDS (WP.12) | J118: 1 | L118: Pendiente | M118: =IF(AND(C118<=FechaCorte,NOT(ISNUMBER(K118))),"Por confirmar","")
A119: 116 | B119: Sprint 2 | C119: 46307 | D119: Pablo Valentín Varela Rivera | E119: WT / Developer – Técnico | F119: T05 | G119: SI.03.03 | H119: Identificar y documentar componentes e interfaces (SDS) | I119: SDS (WP.12) | J119: 2 | L119: Pendiente | M119: =IF(AND(C119<=FechaCorte,NOT(ISNUMBER(K119))),"Por confirmar","")
A120: 114 | B120: Sprint 2 | C120: 46307 | D120: Sebastián Guerra Hernández | E120: WT / Developer – Calidad | F120: T06 | G120: SI.03.02 | H120: Revisar requisitos y diseño antes de construir | I120: Registro de revisión | J120: 1.5 | L120: Pendiente | M120: =IF(AND(C120<=FechaCorte,NOT(ISNUMBER(K120))),"Por confirmar","")
A121: 113 | B121: Sprint 2 | C121: 46307 | D121: Francisco Valdez García | E121: PJM / Scrum Master / Developer | F121: T07 | G121: SI.04.02 | H121: Construir componentes del Sprint Backlog | I121: Componentes (WP.11) | J121: 0.25 | L121: Pendiente | M121: =IF(AND(C121<=FechaCorte,NOT(ISNUMBER(K121))),"Por confirmar","")
A122: 117 | B122: Sprint 2 | C122: 46307 | D122: Pablo Valentín Varela Rivera | E122: WT / Developer – Técnico | F122: T07 | G122: SI.04.02 | H122: Construir componentes del Sprint Backlog | I122: Componentes (WP.11) | J122: 0.75 | L122: Pendiente | M122: =IF(AND(C122<=FechaCorte,NOT(ISNUMBER(K122))),"Por confirmar","")
A123: 115 | B123: Sprint 2 | C123: 46307 | D123: Sebastián Guerra Hernández | E123: WT / Developer – Calidad | F123: T07 | G123: SI.04.02 | H123: Construir componentes del Sprint Backlog | I123: Componentes (WP.11) | J123: 1.25 | L123: Pendiente | M123: =IF(AND(C123<=FechaCorte,NOT(ISNUMBER(K123))),"Por confirmar","")
A124: 119 | B124: Sprint 2 | C124: 46307 | D124: Marco Antonio de Jesús Oliva Santos | E124: WT / Developer – Colaboración | F124: T07 | G124: SI.04.05 | H124: Construir componentes y versionarlos en el repositorio | I124: Componentes (WP.11) | J124: 1.75 | L124: Pendiente | M124: =IF(AND(C124<=FechaCorte,NOT(ISNUMBER(K124))),"Por confirmar","")
A125: 121 | B125: Sprint 2 | C125: 46308 | D125: Francisco Valdez García | E125: PJM / Scrum Master / Developer | F125: T07 | G125: SI.04.02 | H125: Construir componentes del Sprint Backlog | I125: Componentes (WP.11) | J125: 2.75 | L125: Pendiente | M125: =IF(AND(C125<=FechaCorte,NOT(ISNUMBER(K125))),"Por confirmar","")
A126: 123 | B126: Sprint 2 | C126: 46308 | D126: Pablo Valentín Varela Rivera | E126: WT / Developer – Técnico | F126: T07 | G126: SI.04.02 | H126: Construir componentes del Sprint Backlog | I126: Componentes (WP.11) | J126: 0.75 | L126: Pendiente | M126: =IF(AND(C126<=FechaCorte,NOT(ISNUMBER(K126))),"Por confirmar","")
A127: 122 | B127: Sprint 2 | C127: 46308 | D127: Sebastián Guerra Hernández | E127: WT / Developer – Calidad | F127: T07 | G127: SI.04.02 | H127: Construir componentes del Sprint Backlog | I127: Componentes (WP.11) | J127: 0.75 | L127: Pendiente | M127: =IF(AND(C127<=FechaCorte,NOT(ISNUMBER(K127))),"Por confirmar","")
A128: 124 | B128: Sprint 2 | C128: 46308 | D128: Marco Antonio de Jesús Oliva Santos | E128: WT / Developer – Colaboración | F128: T07 | G128: SI.04.05 | H128: Construir componentes y versionarlos en el repositorio | I128: Componentes (WP.11) | J128: 1.25 | L128: Pendiente | M128: =IF(AND(C128<=FechaCorte,NOT(ISNUMBER(K128))),"Por confirmar","")
A129: 126 | B129: Sprint 2 | C129: 46310 | D129: Francisco Valdez García | E129: PJM / Scrum Master / Developer | F129: T07 | G129: SI.04.02 | H129: Construir componentes del Sprint Backlog | I129: Componentes (WP.11) | J129: 2.75 | L129: Pendiente | M129: =IF(AND(C129<=FechaCorte,NOT(ISNUMBER(K129))),"Por confirmar","")
... A163: 169 | B163: Sprint 2 | C163: 46321 | D163: Marco Antonio de Jesús Oliva Santos | E163: WT / Developer – Colaboración | F163: T12 | G163: SI.06.02 | H163: Preparar versión entregable y avance de la Guía de operación | I163: Producto / Guía (WP.13) | J163: 0.75 | L163: Pendiente | M163: =IF(AND(C163<=FechaCorte,NOT(ISNUMBER(K163))),"Por confirmar","")
A164: 266 | B164: Entre sprints | C164: 46304 | D164: Equipo | E164: Equipo; esfuerzo individual por confirmar | F164: T14 | G164: PM.02.01 | H164: Daily Scrum D-15 (entre el cierre del Sprint 1 y el Planning del Sprint 2) | I164: Bitácora Daily Scrum (WP.05) | J164: 0 | K164: 1 | L164: Completado | M164: =IF(AND(C164<=FechaCorte,NOT(ISNUMBER(K164))),"Por confirmar","")
A165: 111 | B165: Sprint 2 | C165: 46307 | D165: Equipo | E165: Scrum Team (4 integrantes) | F165: T14 | G165: PM.02.01 | H165: Daily Scrum (4 × 15 min): revisar avance e impedimentos | I165: Registro de avance (WP.06) | J165: 1 | L165: Pendiente | M165: =IF(AND(C165<=FechaCorte,NOT(ISNUMBER(K165))),"Por confirmar","")
A166: 120 | B166: Sprint 2 | C166: 46308 | D166: Equipo | E166: Scrum Team (4 integrantes) | F166: T14 | G166: PM.02.01 | H166: Daily Scrum (4 × 15 min): revisar avance e impedimentos | I166: Registro de avance (WP.06) | J166: 1 | L166: Pendiente | M166: =IF(AND(C166<=FechaCorte,NOT(ISNUMBER(K166))),"Por confirmar","")
A167: 125 | B167: Sprint 2 | C167: 46310 | D167: Equipo | E167: Scrum Team (4 integrantes) | F167: T14 | G167: PM.02.01 | H167: Daily Scrum (4 × 15 min): revisar avance e impedimentos | I167: Registro de avance (WP.06) | J167: 1 | L167: Pendiente | M167: =IF(AND(C167<=FechaCorte,NOT(ISNUMBER(K167))),"Por confirmar","")
A168: 130 | B168: Sprint 2 | C168: 46311 | D168: Equipo | E168: Scrum Team (4 integrantes) | F168: T14 | G168: PM.02.01 | H168: Daily Scrum (4 × 15 min): revisar avance e impedimentos | I168: Registro de avance (WP.06) | J168: 1 | L168: Pendiente | M168: =IF(AND(C168<=FechaCorte,NOT(ISNUMBER(K168))),"Por confirmar","")
A169: 136 | B169: Sprint 2 | C169: 46315 | D169: Equipo | E169: Scrum Team (4 integrantes) | F169: T14 | G169: PM.02.01 | H169: Daily Scrum (4 × 15 min): revisar avance e impedimentos | I169: Registro de avance (WP.06) | J169: 1 | L169: Pendiente | M169: =IF(AND(C169<=FechaCorte,NOT(ISNUMBER(K169))),"Por confirmar","")
A170: 138 | B170: Sprint 2 | C170: 46315 | D170: Francisco Valdez García | E170: PJM / Scrum Master / Developer | F170: T14 | G170: PM.03.01 | H170: Evaluar avance vs. plan y actualizar el Progress Status Record | I170: Progress Status Record (WP.06) | J170: 1 | L170: Pendiente | M170: =IF(AND(C170<=FechaCorte,NOT(ISNUMBER(K170))),"Por confirmar","")
A171: 145 | B171: Sprint 2 | C171: 46316 | D171: Equipo | E171: Scrum Team (4 integrantes) | F171: T14 | G171: PM.02.01 | H171: Daily Scrum (4 × 15 min): revisar avance e impedimentos | I171: Registro de avance (WP.06) | J171: 1 | L171: Pendiente | M171: =IF(AND(C171<=FechaCorte,NOT(ISNUMBER(K171))),"Por confirmar","")
A172: 154 | B172: Sprint 2 | C172: 46318 | D172: Equipo | E172: Scrum Team (4 integrantes) | F172: T14 | G172: PM.02.01 | H172: Daily Scrum (4 × 15 min): revisar avance e impedimentos | I172: Registro de avance (WP.06) | J172: 1 | L172: Pendiente | M172: =IF(AND(C172<=FechaCorte,NOT(ISNUMBER(K172))),"Por confirmar","")
A173: 157 | B173: Sprint 2 | C173: 46318 | D173: Francisco Valdez García | E173: PJM / Scrum Master / Developer | F173: T14 | G173: PM.03.01 | H173: Evaluar avance vs. plan y actualizar el Progress Status Record | I173: Progress Status Record (WP.06) | J173: 0.25 | L173: Pendiente | M173: =IF(AND(C173<=FechaCorte,NOT(ISNUMBER(K173))),"Por confirmar","")
A174: 162 | B174: Sprint 2 | C174: 46321 | D174: Equipo | E174: Scrum Team (4 integrantes) | F174: T14 | G174: PM.02.01 | H174: Daily Scrum (4 × 15 min): revisar avance e impedimentos | I174: Registro de avance (WP.06) | J174: 1 | L174: Pendiente | M174: =IF(AND(C174<=FechaCorte,NOT(ISNUMBER(K174))),"Por confirmar","")
...

Sheet Plan_T01-T14
A1: ID | B1: Tarea (Project Plan §8) | C1: Resultado esperado | D1: Tareas ISO 29110 | E1: Work Product | F1: Horas Sprints | G1: Horas posteriores | H1: Total plan | I1: Estimación actual en Control_Diario (propuesta de replanificación para el Planning del 12/10) | J1: Diferencia vs. base (h) | K1: Fechas en Control_Diario | L1: Responsable principal
A2: T01 | B2: Generar, revisar y someter a aprobación el Project Plan; mantenerlo actualizado. | C2: Project Plan revisado y aprobación registrada. | D2: PM.01.01–PM.01.09 | E2: WP.07 Project plan | F2: 12 | G2: 0 | H2: =F2+G2 -> 12 | I2: =SUMIF(Control_Diario!$F$2:$F$300,A2,Control_Diario!$J$2:$J$300) -> 12 | J2: =I2-H2 -> 0 | K2: 21/09/2026 – 23/09/2026 | L2: Francisco Valdez García
A3: T02 | B3: Revisar el plan con el equipo; preparar y verificar el entorno por plataforma. | C3: Implementation Environment y evidencias de verificación. | D3: SI.01.01, SI.01.02, PM.01.10 | E3: WP.04, WP.08 | F3: 12 | G3: 0 | H3: =F3+G3 -> 12 | I3: =SUMIF(Control_Diario!$F$2:$F$300,A3,Control_Diario!$J$2:$J$300) -> 12 | J3: =I3-H3 -> 0 | K3: 21/09/2026 – 28/10/2026 | L3: Pablo Valentín Varela Rivera
A4: T03 | B4: Analizar y documentar requisitos; crear y refinar el Product Backlog. | C4: Especificación de requisitos y Product Backlog. | D4: SI.02.02 | E4: WP.09 Requirements specification | F4: 24 | G4: 0 | H4: =F4+G4 -> 24 | I4: =SUMIF(Control_Diario!$F$2:$F$300,A4,Control_Diario!$J$2:$J$300) -> 24 | J4: =I4-H4 -> 0 | K4: 22/09/2026 – 28/10/2026 | L4: Sebastián Guerra Hernández
A5: T04 | B5: Validar y obtener aprobación de requisitos con la cliente; ordenar el Product Backlog. | C5: Requisitos validados y aprobados; Backlog ordenado. | D5: SI.02.03, SI.02.04 | E5: WP.09 [validated, baselined], WP.05 | F5: 12 | G5: 0 | H5: =F5+G5 -> 12 | I5: =SUMIF(Control_Diario!$F$2:$F$300,A5,Control_Diario!$J$2:$J$300) -> 14 | J5: =I5-H5 -> 2 | K5: 23/09/2026 – 29/10/2026 | L5: Francisco Valdez García
A6: T05 | B6: Identificar y documentar componentes e interfaces de los elementos seleccionados. | C6: Especificación de componentes. | D6: SI.03.03 | E6: WP.12 Software components specification | F6: 24 | G6: 0 | H6: =F6+G6 -> 24 | I6: =SUMIF(Control_Diario!$F$2:$F$300,A6,Control_Diario!$J$2:$J$300) -> 24 | J6: =I6-H6 -> 0 | K6: 23/09/2026 – 30/10/2026 | L6: Pablo Valentín Varela Rivera
A7: T06 | B7: Revisar el diseño antes de construir los componentes correspondientes. | C7: Diseño revisado y observaciones atendidas. | D7: SI.03.02, SI.03.04 | E7: WP.12 [baselined] | F7: 12 | G7: 0 | H7: =F7+G7 -> 12 | I7: =SUMIF(Control_Diario!$F$2:$F$300,A7,Control_Diario!$J$2:$J$300) -> 12 | J7: =I7-H7 -> 0 | K7: 23/09/2026 – 29/10/2026 | L7: Sebastián Guerra Hernández
A8: T07 | B8: Construir los componentes del alcance seleccionado. | C8: Componentes de software versionados. | D8: SI.04.02, SI.04.05 | E8: WP.11 Software components | F8: 96 | G8: 0 | H8: =F8+G8 -> 96 | I8: =SUMIF(Control_Diario!$F$2:$F$300,A8,Control_Diario!$J$2:$J$300) -> 90 | J8: =I8-H8 -> -6 | K8: 28/09/2026 – 09/11/2026 | L8: Pablo Valentín Varela Rivera
A9: T08 | B9: Preparar y ejecutar pruebas unitarias y de widgets; corregir defectos. | C9: Componentes probados y resultados registrados. | D9: SI.04.03, SI.04.04 | E9: WP.14 Test cases and test procedures | F9: 36 | G9: 0 | H9: =F9+G9 -> 36 | I9: =SUMIF(Control_Diario!$F$2:$F$300,A9,Control_Diario!$J$2:$J$300) -> 36 | J9: =I9-H9 -> 0 | K9: 29/09/2026 – 10/11/2026 | L9: Sebastián Guerra Hernández
A10: T09 | B10: Integrar componentes durante el Sprint conforme se completen. | C10: Incremento integrado y disponible para comprobar sus flujos. | D10: SI.05.03 | E10: WP.10 Software | F10: 18 | G10: 0 | H10: =F10+G10 -> 18 | I10: =SUMIF(Control_Diario!$F$2:$F$300,A10,Control_Diario!$J$2:$J$300) -> 18 | J10: =I10-H10 -> 0 | K10: 01/10/2026 – 12/11/2026 | L10: Pablo Valentín Varela Rivera
A11: T10 | B11: Ejecutar pruebas de integración, registrar resultados y corregir defectos. | C11: Resultados de pruebas e incremento verificado. | D11: SI.05.02, SI.05.04, SI.05.05 | E11: WP.14, WP.15 Test report | F11: 30 | G11: 0 | H11: =F11+G11 -> 30 | I11: =SUMIF(Control_Diario!$F$2:$F$300,A11,Control_Diario!$J$2:$J$300) -> 30 | J11: =I11-H11 -> 0 | K11: 05/10/2026 – 12/11/2026 | L11: Sebastián Guerra Hernández
A12: T11 | B12: Realizar Sprint Review y registrar acuerdos; validar el producto final. | C12: Incremento revisado, retroalimentación y validación final registrada. | D12: PM.02.02, SI.05.06 | E12: WP.05 Meeting record | F12: 12 | G12: 4 | H12: =F12+G12 -> 16 | I12: =SUMIF(Control_Diario!$F$2:$F$300,A12,Control_Diario!$J$2:$J$300) -> 16 | J12: =I12-H12 -> 0 | K12: 02/10/2026 – 19/11/2026 | L12: Francisco Valdez García
A13: T12 | B13: Preparar la versión entregable, la guía de operación y el paquete de entrega. | C13: Producto preparado e instrucciones de instalación comprobadas. | D13: SI.06.01, SI.06.02 | E13: WP.13 Software product | F13: 12 | G13: 20 | H13: =F13+G13 -> 32 | I13: =SUMIF(Control_Diario!$F$2:$F$300,A13,Control_Diario!$J$2:$J$300) -> 32 | J13: =I13-H13 -> 0 | K13: 05/10/2026 – 17/11/2026 | L13: Marco Antonio de Jesús Oliva Santos
... A15: T14 | B15: Monitorear esfuerzo, avance, reuniones, cambios, riesgos y desviaciones. | C15: Registros de progreso, acuerdos, cambios y acciones. | D15: PM.02.01, PM.03.01–PM.03.03 | E15: WP.06, WP.05 | F15: 60 | G15: 4 | H15: =F15+G15 -> 64 | I15: =SUMIF(Control_Diario!$F$2:$F$300,A15,Control_Diario!$J$2:$J$300) -> 68 | J15: =I15-H15 -> 4 | K15: 21/09/2026 – 18/11/2026 | L15: Francisco Valdez García
A16: Total | F16: =SUM(F2:F15) -> 360 | G16: =SUM(G2:G15) -> 36 | H16: =SUM(H2:H15) -> 396 | I16: =SUM(I2:I15) -> 396 | J16: =SUM(J2:J15) -> 0
A18: Base: estimación original del Project Plan (396 h). Estimación actual: redistribución propuesta el 08/10 para el Sprint 2 (T04 +2 h por la sesión con la cliente, T14 +4 h por dailies faltantes, T07 −6 h). El total no cambia; se confirma en el Sprint Planning del 12/10.
